Workbook

Sheet Instructions
A1: Section | B1: Detail
A2: Data Management Dashboard — Master Data Source
A4: How this workbook works
A5: This file is the single source of truth for app.py. Update it weekly: for every module/item, add the row for the new Week number in Weekly_Data (and Governance_Domains). The dashboard filters everything by the Month + Week you pick in the app, showing data accumulated from Week 1 up to that point.
A6: Weeks run 1-48 across the year (4 weeks per month, Jan=weeks 1-4 ... Dec=weeks 45-48).
A7: Weeks 25-48 (Jul-Dec) are pre-loaded as 0 / blank placeholders — fill them in as those weeks happen.
A8: Portfolio."Source" = "Manual (ref. Jira)" for Cheves/General Scaling: numbers are typed by hand after checking Jira, not pulled automatically. Change to "Jira (auto)" only once a real API/Power BI connection exists.
A9: Sheet guide
A10: Portfolio | B10: The 6 top-level projects (structural info only: name, type, description, source, owner).
A11: Weekly_Data | B11: Progress%, Planned%, OpenTickets, ClosedThisWeek per Module+Item+Week. Weeks 1-24: real reported history (typed, frozen, do not overwrite). Weeks 25-48, for Cheves/Rollout/AIAgents/SOKnowledge: computed by formula from Tasks (nothing to type). Portfolio-rollup rows (Cheves Value Pack, General Scaling, AI Models Integration Agent, SO Knowledge Integration Agent) are also formulas, averaging/summing their sub-items. Status/ScheduleStatus and the Governance/Executive Portfolio rows stay manual by design.
A12: Weeks | B12: Reference table only: translates Week number (1-48) to a real calendar date (2026). Used by formulas in Phases, Weekly_Data and Team_Load to answer 'what did this look like as of week X'. Never edit.
A13: Tasks | B13: Master ticket ledger for Cheves, General Scaling, AI Models Integration Agent and SO Knowledge Integration Agent. One row per ticket: DateCreated, PlannedDate, DateClosed (leave DateClosed blank while open). Everything else (Phases%, Weekly_Data%, Team_Load) is calculated FROM this sheet — type a ticket once, never repeat it week to week.
A14: Phases | B14: Weekly Progress% per phase, computed from Tasks (COUNTIFS by Phase, as of that week's date via the Weeks table). Weeks 1-24: blank — this sheet did not track weekly history before this rebuild, so it is honestly empty rather than guessed.
A15: Milestones | B15: Same 5/4 checkpoints as before, now with a PhaseName column linking each milestone to its phase. Done/WeekCompleted stay a manual confirmation (milestones are business gates, e.g. 'Operator training', not always identical to a phase hitting 100%).
A16: Team_Load | B16: Computed pivot of Tasks by Responsible (Kevin/Jazmin) x Module x Week (25-48). Nothing to type — reflects whoever is set in Tasks!Responsible.
A17: Governance_Domains | B17: Weekly Stage(0-4), Cataloged%, OwnerAssigned%, PlanningProgress%, PipelineStatus, DashboardStatus, DatasetsOK%, Issues, Backlog, Notes per domain. Manual (maturity judgment, not ticket-driven).
A18: Governance_Datasets | B18: Catalog of prioritized datasets per domain, with Owner, Steward, QualityRule, Threshold. Blank Owner/QualityRule = not assigned yet. Latest known state, manual.
A19: Governance_Plan | B19: Target maturity stage and target date per domain, to compare actual Stage(0-4) against plan.
A20: Executive_Cycle_Current | B20: This month's 5-milestone checklist (planned day offset + Done/ActualDayOffset). Reset manually at the start of each new month.
A21: Executive_Cycle_History | B21: Planned vs Actual day per month, Jan-Dec. Jul-Dec pre-loaded at 0 — fill in as each month closes.
... A31: Stage 5: Monitoring & Continuous Improvement | B31: Track data quality over time and resolve recurring issues through a backlog.

Sheet Portfolio
A1: ProjectID | B1: Name | C1: Type | D1: Description | E1: Source | F1: Owner
A2: P1 | B2: Cheves Value Pack | C2: B | D2: Anomaly Detection, CWS & UH Prediction bundle | E2: Manual (ref. Jira) | F2: Kevin
A3: P2 | B3: General Scaling | C3: B | D3: Fleet-wide expansion: Cahua, Yaupi, Malpaso | E3: Manual (ref. Jira) | F3: Kevin
A4: P3 | B4: AI Models Integration Agent | C4: B | D4: Operator-facing AI models agent | E4: Manual | F4: Jazmin
A5: P4 | B5: SO Knowledge Integration Agent | C5: B | D5: Technical Q&A over ACRs & O&M manuals | E5: Manual | F5: Jazmin
A6: P5 | B6: Data Governance MVP | C6: C | D6: 4-domain data governance maturity rollout | E6: Manual | F6: Jazmin
A7: P6 | B7: Executive Dashboard | C7: A | D7: Monthly recurring management report | E7: Manual | F7: Jazmin

Sheet Weekly_Data
A1: Module | B1: Item | C1: Week | D1: Month | E1: WeekInMonth | F1: Progress% | G1: Planned% | H1: ScheduleStatus | I1: OpenTickets | J1: ClosedThisWeek
A2: Portfolio | B2: Cheves Value Pack | C2: 1 | D2: 1 | E2: 1 | F2: =IFERROR(ROUND(AVERAGEIFS(Weekly_Data!$F:$F,Weekly_Data!$A:$A,"Cheves",Weekly_Data!$C:$C,$C2),0),"") -> 17 | G2: =IFERROR(ROUND(AVERAGEIFS(Weekly_Data!$G:$G,Weekly_Data!$A:$A,"Cheves",Weekly_Data!$C:$C,$C2),0),"") -> 0 | H2: No Deviation | I2: =SUMIFS(Weekly_Data!$I:$I,Weekly_Data!$A:$A,"Cheves",Weekly_Data!$C:$C,$C2) -> 3 | J2: =SUMIFS(Weekly_Data!$J:$J,Weekly_Data!$A:$A,"Cheves",Weekly_Data!$C:$C,$C2) -> 1
A3: Portfolio | B3: Cheves Value Pack | C3: 2 | D3: 1 | E3: 2 | F3: =IFERROR(ROUND(AVERAGEIFS(Weekly_Data!$F:$F,Weekly_Data!$A:$A,"Cheves",Weekly_Data!$C:$C,$C3),0),"") -> 17 | G3: =IFERROR(ROUND(AVERAGEIFS(Weekly_Data!$G:$G,Weekly_Data!$A:$A,"Cheves",Weekly_Data!$C:$C,$C3),0),"") -> 0 | H3: No Deviation | I3: =SUMIFS(Weekly_Data!$I:$I,Weekly_Data!$A:$A,"Cheves",Weekly_Data!$C:$C,$C3) -> 3 | J3: =SUMIFS(Weekly_Data!$J:$J,Weekly_Data!$A:$A,"Cheves",Weekly_Data!$C:$C,$C3) -> 0
A4: Portfolio | B4: Cheves Value Pack | C4: 3 | D4: 1 | E4: 3 | F4: =IFERROR(ROUND(AVERAGEIFS(Weekly_Data!$F:$F,Weekly_Data!$A:$A,"Cheves",Weekly_Data!$C:$C,$C4),0),"") -> 33 | G4: =IFERROR(ROUND(AVERAGEIFS(Weekly_Data!$G:$G,Weekly_Data!$A:$A,"Cheves",Weekly_Data!$C:$C,$C4),0),"") -> 0 | H4: No Deviation | I4: =SUMIFS(Weekly_Data!$I:$I,Weekly_Data!$A:$A,"Cheves",Weekly_Data!$C:$C,$C4) -> 2 | J4: =SUMIFS(Weekly_Data!$J:$J,Weekly_Data!$A:$A,"Cheves",Weekly_Data!$C:$C,$C4) -> 1
A5: Portfolio | B5: Cheves Value Pack | C5: 4 | D5: 1 | E5: 4 | F5: =IFERROR(ROUND(AVERAGEIFS(Weekly_Data!$F:$F,Weekly_Data!$A:$A,"Cheves",Weekly_Data!$C:$C,$C5),0),"") -> 33 | G5: =IFERROR(ROUND(AVERAGEIFS(Weekly_Data!$G:$G,Weekly_Data!$A:$A,"Cheves",Weekly_Data!$C:$C,$C5),0),"") -> 0 | H5: No Deviation | I5: =SUMIFS(Weekly_Data!$I:$I,Weekly_Data!$A:$A,"Cheves",Weekly_Data!$C:$C,$C5) -> 2 | J5: =SUMIFS(Weekly_Data!$J:$J,Weekly_Data!$A:$A,"Cheves",Weekly_Data!$C:$C,$C5) -> 0
A6: Portfolio | B6: Cheves Value Pack | C6: 5 | D6: 1 | E6: 5 | F6: =IFERROR(ROUND(AVERAGEIFS(Weekly_Data!$F:$F,Weekly_Data!$A:$A,"Cheves",Weekly_Data!$C:$C,$C6),0),"") -> 33 | G6: =IFERROR(ROUND(AVERAGEIFS(Weekly_Data!$G:$G,Weekly_Data!$A:$A,"Cheves",Weekly_Data!$C:$C,$C6),0),"") -> 0 | H6: No Deviation | I6: =SUMIFS(Weekly_Data!$I:$I,Weekly_Data!$A:$A,"Cheves",Weekly_Data!$C:$C,$C6) -> 2 | J6: =SUMIFS(Weekly_Data!$J:$J,Weekly_Data!$A:$A,"Cheves",Weekly_Data!$C:$C,$C6) -> 0
A7: Portfolio | B7: Cheves Value Pack | C7: 6 | D7: 2 | E7: 1 | F7: =IFERROR(ROUND(AVERAGEIFS(Weekly_Data!$F:$F,Weekly_Data!$A:$A,"Cheves",Weekly_Data!$C:$C,$C7),0),"") -> 33 | G7: =IFERROR(ROUND(AVERAGEIFS(Weekly_Data!$G:$G,Weekly_Data!$A:$A,"Cheves",Weekly_Data!$C:$C,$C7),0),"") -> 0 | H7: No Deviation | I7: =SUMIFS(Weekly_Data!$I:$I,Weekly_Data!$A:$A,"Cheves",Weekly_Data!$C:$C,$C7) -> 2 | J7: =SUMIFS(Weekly_Data!$J:$J,Weekly_Data!$A:$A,"Cheves",Weekly_Data!$C:$C,$C7) -> 0
A8: Portfolio | B8: Cheves Value Pack | C8: 7 | D8: 2 | E8: 2 | F8: =IFERROR(ROUND(AVERAGEIFS(Weekly_Data!$F:$F,Weekly_Data!$A:$A,"Cheves",Weekly_Data!$C:$C,$C8),0),"") -> 33 | G8: =IFERROR(ROUND(AVERAGEIFS(Weekly_Data!$G:$G,Weekly_Data!$A:$A,"Cheves",Weekly_Data!$C:$C,$C8),0),"") -> 0 | H8: No Deviation | I8: =SUMIFS(Weekly_Data!$I:$I,Weekly_Data!$A:$A,"Cheves",Weekly_Data!$C:$C,$C8) -> 2 | J8: =SUMIFS(Weekly_Data!$J:$J,Weekly_Data!$A:$A,"Cheves",Weekly_Data!$C:$C,$C8) -> 0
A9: Portfolio | B9: Cheves Value Pack | C9: 8 | D9: 2 | E9: 3 | F9: =IFERROR(ROUND(AVERAGEIFS(Weekly_Data!$F:$F,Weekly_Data!$A:$A,"Cheves",Weekly_Data!$C:$C,$C9),0),"") -> 33 | G9: =IFERROR(ROUND(AVERAGEIFS(Weekly_Data!$G:$G,Weekly_Data!$A:$A,"Cheves",Weekly_Data!$C:$C,$C9),0),"") -> 0 | H9: No Deviation | I9: =SUMIFS(Weekly_Data!$I:$I,Weekly_Data!$A:$A,"Cheves",Weekly_Data!$C:$C,$C9) -> 2 | J9: =SUMIFS(Weekly_Data!$J:$J,Weekly_Data!$A:$A,"Cheves",Weekly_Data!$C:$C,$C9) -> 0
A10: Portfolio | B10: Cheves Value Pack | C10: 9 | D10: 2 | E10: 4 | F10: =IFERROR(ROUND(AVERAGEIFS(Weekly_Data!$F:$F,Weekly_Data!$A:$A,"Cheves",Weekly_Data!$C:$C,$C10),0),"") -> 33 | G10: =IFERROR(ROUND(AVERAGEIFS(Weekly_Data!$G:$G,Weekly_Data!$A:$A,"Cheves",Weekly_Data!$C:$C,$C10),0),"") -> 0 | H10: No Deviation | I10: =SUMIFS(Weekly_Data!$I:$I,Weekly_Data!$A:$A,"Cheves",Weekly_Data!$C:$C,$C10) -> 2 | J10: =SUMIFS(Weekly_Data!$J:$J,Weekly_Data!$A:$A,"Cheves",Weekly_Data!$C:$C,$C10) -> 0
A11: Portfolio | B11: Cheves Value Pack | C11: 10 | D11: 3 | E11: 1 | F11: =IFERROR(ROUND(AVERAGEIFS(Weekly_Data!$F:$F,Weekly_Data!$A:$A,"Cheves",Weekly_Data!$C:$C,$C11),0),"") -> 33 | G11: =IFERROR(ROUND(AVERAGEIFS(Weekly_Data!$G:$G,Weekly_Data!$A:$A,"Cheves",Weekly_Data!$C:$C,$C11),0),"") -> 0 | H11: No Deviation | I11: =SUMIFS(Weekly_Data!$I:$I,Weekly_Data!$A:$A,"Cheves",Weekly_Data!$C:$C,$C11) -> 2 | J11: =SUMIFS(Weekly_Data!$J:$J,Weekly_Data!$A:$A,"Cheves",Weekly_Data!$C:$C,$C11) -> 0
A12: Portfolio | B12: Cheves Value Pack | C12: 11 | D12: 3 | E12: 2 | F12: =IFERROR(ROUND(AVERAGEIFS(Weekly_Data!$F:$F,Weekly_Data!$A:$A,"Cheves",Weekly_Data!$C:$C,$C12),0),"") -> 33 | G12: =IFERROR(ROUND(AVERAGEIFS(Weekly_Data!$G:$G,Weekly_Data!$A:$A,"Cheves",Weekly_Data!$C:$C,$C12),0),"") -> 0 | H12: No Deviation | I12: =SUMIFS(Weekly_Data!$I:$I,Weekly_Data!$A:$A,"Cheves",Weekly_Data!$C:$C,$C12) -> 2 | J12: =SUMIFS(Weekly_Data!$J:$J,Weekly_Data!$A:$A,"Cheves",Weekly_Data!$C:$C,$C12) -> 0
A13: Portfolio | B13: Cheves Value Pack | C13: 12 | D13: 3 | E13: 3 | F13: =IFERROR(ROUND(AVERAGEIFS(Weekly_Data!$F:$F,Weekly_Data!$A:$A,"Cheves",Weekly_Data!$C:$C,$C13),0),"") -> 33 | G13: =IFERROR(ROUND(AVERAGEIFS(Weekly_Data!$G:$G,Weekly_Data!$A:$A,"Cheves",Weekly_Data!$C:$C,$C13),0),"") -> 0 | H13: No Deviation | I13: =SUMIFS(Weekly_Data!$I:$I,Weekly_Data!$A:$A,"Cheves",Weekly_Data!$C:$C,$C13) -> 2 | J13: =SUMIFS(Weekly_Data!$J:$J,Weekly_Data!$A:$A,"Cheves",Weekly_Data!$C:$C,$C13) -> 0
... A25: Portfolio | B25: Cheves Value Pack | C25: 24 | D25: 6 | E25: 2 | F25: =IFERROR(ROUND(AVERAGEIFS(Weekly_Data!$F:$F,Weekly_Data!$A:$A,"Cheves",Weekly_Data!$C:$C,$C25),0),"") -> 50 | G25: =IFERROR(ROUND(AVERAGEIFS(Weekly_Data!$G:$G,Weekly_Data!$A:$A,"Cheves",Weekly_Data!$C:$C,$C25),0),"") -> 17 | H25: No Deviation | I25: =SUMIFS(Weekly_Data!$I:$I,Weekly_Data!$A:$A,"Cheves",Weekly_Data!$C:$C,$C25) -> 1 | J25: =SUMIFS(Weekly_Data!$J:$J,Weekly_Data!$A:$A,"Cheves",Weekly_Data!$C:$C,$C25) -> 1
A26: Portfolio | B26: Cheves Value Pack | C26: 25 | D26: 6 | E26: 3 | F26: =IFERROR(ROUND(AVERAGEIFS(Weekly_Data!$F:$F,Weekly_Data!$A:$A,"Cheves",Weekly_Data!$C:$C,$C26),0),"") -> 50 | G26: =IFERROR(ROUND(AVERAGEIFS(Weekly_Data!$G:$G,Weekly_Data!$A:$A,"Cheves",Weekly_Data!$C:$C,$C26),0),"") -> 17 | I26: =SUMIFS(Weekly_Data!$I:$I,Weekly_Data!$A:$A,"Cheves",Weekly_Data!$C:$C,$C26) -> 1 | J26: =SUMIFS(Weekly_Data!$J:$J,Weekly_Data!$A:$A,"Cheves",Weekly_Data!$C:$C,$C26) -> 0
A27: Portfolio | B27: Cheves Value Pack | C27: 26 | D27: 6 | E27: 4 | F27: =IFERROR(ROUND(AVERAGEIFS(Weekly_Data!$F:$F,Weekly_Data!$A:$A,"Cheves",Weekly_Data!$C:$C,$C27),0),"") -> 50 | G27: =IFERROR(ROUND(AVERAGEIFS(Weekly_Data!$G:$G,Weekly_Data!$A:$A,"Cheves",Weekly_Data!$C:$C,$C27),0),"") -> 17 | I27: =SUMIFS(Weekly_Data!$I:$I,Weekly_Data!$A:$A,"Cheves",Weekly_Data!$C:$C,$C27) -> 1 | J27: =SUMIFS(Weekly_Data!$J:$J,Weekly_Data!$A:$A,"Cheves",Weekly_Data!$C:$C,$C27) -> 0
A28: Portfolio | B28: Cheves Value Pack | C28: 27 | D28: 7 | E28: 1 | F28: =IFERROR(ROUND(AVERAGEIFS(Weekly_Data!$F:$F,Weekly_Data!$A:$A,"Cheves",Weekly_Data!$C:$C,$C28),0),"") -> 50 | G28: =IFERROR(ROUND(AVERAGEIFS(Weekly_Data!$G:$G,Weekly_Data!$A:$A,"Cheves",Weekly_Data!$C:$C,$C28),0),"") -> 17 | I28: =SUMIFS(Weekly_Data!$I:$I,Weekly_Data!$A:$A,"Cheves",Weekly_Data!$C:$C,$C28) -> 1 | J28: =SUMIFS(Weekly_Data!$J:$J,Weekly_Data!$A:$A,"Cheves",Weekly_Data!$C:$C,$C28) -> 0
A29: Portfolio | B29: Cheves Value Pack | C29: 28 | D29: 7 | E29: 2 | F29: =IFERROR(ROUND(AVERAGEIFS(Weekly_Data!$F:$F,Weekly_Data!$A:$A,"Cheves",Weekly_Data!$C:$C,$C29),0),"") -> 50 | G29: =IFERROR(ROUND(AVERAGEIFS(Weekly_Data!$G:$G,Weekly_Data!$A:$A,"Cheves",Weekly_Data!$C:$C,$C29),0),"") -> 17 | I29: =SUMIFS(Weekly_Data!$I:$I,Weekly_Data!$A:$A,"Cheves",Weekly_Data!$C:$C,$C29) -> 1 | J29: =SUMIFS(Weekly_Data!$J:$J,Weekly_Data!$A:$A,"Cheves",Weekly_Data!$C:$C,$C29) -> 0
A30: Portfolio | B30: Cheves Value Pack | C30: 29 | D30: 7 | E30: 3 | F30: =IFERROR(ROUND(AVERAGEIFS(Weekly_Data!$F:$F,Weekly_Data!$A:$A,"Cheves",Weekly_Data!$C:$C,$C30),0),"") -> 50 | G30: =IFERROR(ROUND(AVERAGEIFS(Weekly_Data!$G:$G,Weekly_Data!$A:$A,"Cheves",Weekly_Data!$C:$C,$C30),0),"") -> 17 | I30: =SUMIFS(Weekly_Data!$I:$I,Weekly_Data!$A:$A,"Cheves",Weekly_Data!$C:$C,$C30) -> 1 | J30: =SUMIFS(Weekly_Data!$J:$J,Weekly_Data!$A:$A,"Cheves",Weekly_Data!$C:$C,$C30) -> 0
A31: Portfolio | B31: Cheves Value Pack | C31: 30 | D31: 7 | E31: 4 | F31: =IFERROR(ROUND(AVERAGEIFS(Weekly_Data!$F:$F,Weekly_Data!$A:$A,"Cheves",Weekly_Data!$C:$C,$C31),0),"") -> 50 | G31: =IFERROR(ROUND(AVERAGEIFS(Weekly_Data!$G:$G,Weekly_Data!$A:$A,"Cheves",Weekly_Data!$C:$C,$C31),0),"") -> 17 | I31: =SUMIFS(Weekly_Data!$I:$I,Weekly_Data!$A:$A,"Cheves",Weekly_Data!$C:$C,$C31) -> 1 | J31: =SUMIFS(Weekly_Data!$J:$J,Weekly_Data!$A:$A,"Cheves",Weekly_Data!$C:$C,$C31) -> 0
A32: Portfolio | B32: Cheves Value Pack | C32: 31 | D32: 8 | E32: 1 | F32: =IFERROR(ROUND(AVERAGEIFS(Weekly_Data!$F:$F,Weekly_Data!$A:$A,"Cheves",Weekly_Data!$C:$C,$C32),0),"") -> 50 | G32: =IFERROR(ROUND(AVERAGEIFS(Weekly_Data!$G:$G,Weekly_Data!$A:$A,"Cheves",Weekly_Data!$C:$C,$C32),0),"") -> 17 | I32: =SUMIFS(Weekly_Data!$I:$I,Weekly_Data!$A:$A,"Cheves",Weekly_Data!$C:$C,$C32) -> 1 | J32: =SUMIFS(Weekly_Data!$J:$J,Weekly_Data!$A:$A,"Cheves",Weekly_Data!$C:$C,$C32) -> 0
A33: Portfolio | B33: Cheves Value Pack | C33: 32 | D33: 8 | E33: 2 | F33: =IFERROR(ROUND(AVERAGEIFS(Weekly_Data!$F:$F,Weekly_Data!$A:$A,"Cheves",Weekly_Data!$C:$C,$C33),0),"") -> 50 | G33: =IFERROR(ROUND(AVERAGEIFS(Weekly_Data!$G:$G,Weekly_Data!$A:$A,"Cheves",Weekly_Data!$C:$C,$C33),0),"") -> 17 | I33: =SUMIFS(Weekly_Data!$I:$I,Weekly_Data!$A:$A,"Cheves",Weekly_Data!$C:$C,$C33) -> 1 | J33: =SUMIFS(Weekly_Data!$J:$J,Weekly_Data!$A:$A,"Cheves",Weekly_Data!$C:$C,$C33) -> 0
A34: Portfolio | B34: Cheves Value Pack | C34: 33 | D34: 8 | E34: 3 | F34: =IFERROR(ROUND(AVERAGEIFS(Weekly_Data!$F:$F,Weekly_Data!$A:$A,"Cheves",Weekly_Data!$C:$C,$C34),0),"") -> 50 | G34: =IFERROR(ROUND(AVERAGEIFS(Weekly_Data!$G:$G,Weekly_Data!$A:$A,"Cheves",Weekly_Data!$C:$C,$C34),0),"") -> 17 | I34: =SUMIFS(Weekly_Data!$I:$I,Weekly_Data!$A:$A,"Cheves",Weekly_Data!$C:$C,$C34) -> 1 | J34: =SUMIFS(Weekly_Data!$J:$J,Weekly_Data!$A:$A,"Cheves",Weekly_Data!$C:$C,$C34) -> 0
A35: Portfolio | B35: Cheves Value Pack | C35: 34 | D35: 8 | E35: 4 | F35: =IFERROR(ROUND(AVERAGEIFS(Weekly_Data!$F:$F,Weekly_Data!$A:$A,"Cheves",Weekly_Data!$C:$C,$C35),0),"") -> 50 | G35: =IFERROR(ROUND(AVERAGEIFS(Weekly_Data!$G:$G,Weekly_Data!$A:$A,"Cheves",Weekly_Data!$C:$C,$C35),0),"") -> 17 | I35: =SUMIFS(Weekly_Data!$I:$I,Weekly_Data!$A:$A,"Cheves",Weekly_Data!$C:$C,$C35) -> 1 | J35: =SUMIFS(Weekly_Data!$J:$J,Weekly_Data!$A:$A,"Cheves",Weekly_Data!$C:$C,$C35) -> 0
A36: Portfolio | B36: Cheves Value Pack | C36: 35 | D36: 8 | E36: 5 | F36: =IFERROR(ROUND(AVERAGEIFS(Weekly_Data!$F:$F,Weekly_Data!$A:$A,"Cheves",Weekly_Data!$C:$C,$C36),0),"") -> 50 | G36: =IFERROR(ROUND(AVERAGEIFS(Weekly_Data!$G:$G,Weekly_Data!$A:$A,"Cheves",Weekly_Data!$C:$C,$C36),0),"") -> 17 | I36: =SUMIFS(Weekly_Data!$I:$I,Weekly_Data!$A:$A,"Cheves",Weekly_Data!$C:$C,$C36) -> 1 | J36: =SUMIFS(Weekly_Data!$J:$J,Weekly_Data!$A:$A,"Cheves",Weekly_Data!$C:$C,$C36) -> 0
A37: Portfolio | B37: Cheves Value Pack | C37: 36 | D37: 9 | E37: 1 | F37: =IFERROR(ROUND(AVERAGEIFS(Weekly_Data!$F:$F,Weekly_Data!$A:$A,"Cheves",Weekly_Data!$C:$C,$C37),0),"") -> 50 | G37: =IFERROR(ROUND(AVERAGEIFS(Weekly_Data!$G:$G,Weekly_Data!$A:$A,"Cheves",Weekly_Data!$C:$C,$C37),0),"") -> 17 | I37: =SUMIFS(Weekly_Data!$I:$I,Weekly_Data!$A:$A,"Cheves",Weekly_Data!$C:$C,$C37) -> 1 | J37: =SUMIFS(Weekly_Data!$J:$J,Weekly_Data!$A:$A,"Cheves",Weekly_Data!$C:$C,$C37) -> 0
... A53: Portfolio | B53: Cheves Value Pack | C53: 52 | D53: 12 | E53: 4 | F53: =IFERROR(ROUND(AVERAGEIFS(Weekly_Data!$F:$F,Weekly_Data!$A:$A,"Cheves",Weekly_Data!$C:$C,$C53),0),"") -> 50 | G53: =IFERROR(ROUND(AVERAGEIFS(Weekly_Data!$G:$G,Weekly_Data!$A:$A,"Cheves",Weekly_Data!$C:$C,$C53),0),"") -> 17 | I53: =SUMIFS(Weekly_Data!$I:$I,Weekly_Data!$A:$A,"Cheves",Weekly_Data!$C:$C,$C53) -> 1 | J53: =SUMIFS(Weekly_Data!$J:$J,Weekly_Data!$A:$A,"Cheves",Weekly_Data!$C:$C,$C53) -> 0
A54: Portfolio | B54: General Scaling | C54: 1 | D54: 1 | E54: 1 | F54: =IFERROR(ROUND(AVERAGEIFS(Weekly_Data!$F:$F,Weekly_Data!$A:$A,"Rollout",Weekly_Data!$C:$C,$C54),0),"") | G54: =IFERROR(ROUND(AVERAGEIFS(Weekly_Data!$G:$G,Weekly_Data!$A:$A,"Rollout",Weekly_Data!$C:$C,$C54),0),"") | H54: Moderate Deviation | I54: =SUMIFS(Weekly_Data!$I:$I,Weekly_Data!$A:$A,"Rollout",Weekly_Data!$C:$C,$C54) -> 0 | J54: =SUMIFS(Weekly_Data!$J:$J,Weekly_Data!$A:$A,"Rollout",Weekly_Data!$C:$C,$C54) -> 0
A55: Portfolio | B55: General Scaling | C55: 2 | D55: 1 | E55: 2 | F55: =IFERROR(ROUND(AVERAGEIFS(Weekly_Data!$F:$F,Weekly_Data!$A:$A,"Rollout",Weekly_Data!$C:$C,$C55),0),"") | G55: =IFERROR(ROUND(AVERAGEIFS(Weekly_Data!$G:$G,Weekly_Data!$A:$A,"Rollout",Weekly_Data!$C:$C,$C55),0),"") | H55: Moderate Deviation | I55: =SUMIFS(Weekly_Data!$I:$I,Weekly_Data!$A:$A,"Rollout",Weekly_Data!$C:$C,$C55) -> 0 | J55: =SUMIFS(Weekly_Data!$J:$J,Weekly_Data!$A:$A,"Rollout",Weekly_Data!$C:$C,$C55) -> 0
A56: Portfolio | B56: General Scaling | C56: 3 | D56: 1 | E56: 3 | F56: =IFERROR(ROUND(AVERAGEIFS(Weekly_Data!$F:$F,Weekly_Data!$A:$A,"Rollout",Weekly_Data!$C:$C,$C56),0),"") | G56: =IFERROR(ROUND(AVERAGEIFS(Weekly_Data!$G:$G,Weekly_Data!$A:$A,"Rollout",Weekly_Data!$C:$C,$C56),0),"") | H56: Moderate Deviation | I56: =SUMIFS(Weekly_Data!$I:$I,Weekly_Data!$A:$A,"Rollout",Weekly_Data!$C:$C,$C56) -> 0 | J56: =SUMIFS(Weekly_Data!$J:$J,Weekly_Data!$A:$A,"Rollout",Weekly_Data!$C:$C,$C56) -> 0
A57: Portfolio | B57: General Scaling | C57: 4 | D57: 1 | E57: 4 | F57: =IFERROR(ROUND(AVERAGEIFS(Weekly_Data!$F:$F,Weekly_Data!$A:$A,"Rollout",Weekly_Data!$C:$C,$C57),0),"") | G57: =IFERROR(ROUND(AVERAGEIFS(Weekly_Data!$G:$G,Weekly_Data!$A:$A,"Rollout",Weekly_Data!$C:$C,$C57),0),"") | H57: Moderate Deviation | I57: =SUMIFS(Weekly_Data!$I:$I,Weekly_Data!$A:$A,"Rollout",Weekly_Data!$C:$C,$C57) -> 0 | J57: =SUMIFS(Weekly_Data!$J:$J,Weekly_Data!$A:$A,"Rollout",Weekly_Data!$C:$C,$C57) -> 0
A58: Portfolio | B58: General Scaling | C58: 5 | D58: 1 | E58: 5 | F58: =IFERROR(ROUND(AVERAGEIFS(Weekly_Data!$F:$F,Weekly_Data!$A:$A,"Rollout",Weekly_Data!$C:$C,$C58),0),"") | G58: =IFERROR(ROUND(AVERAGEIFS(Weekly_Data!$G:$G,Weekly_Data!$A:$A,"Rollout",Weekly_Data!$C:$C,$C58),0),"") | H58: Moderate Deviation | I58: =SUMIFS(Weekly_Data!$I:$I,Weekly_Data!$A:$A,"Rollout",Weekly_Data!$C:$C,$C58) -> 0 | J58: =SUMIFS(Weekly_Data!$J:$J,Weekly_Data!$A:$A,"Rollout",Weekly_Data!$C:$C,$C58) -> 0
A59: Portfolio | B59: General Scaling | C59: 6 | D59: 2 | E59: 1 | F59: =IFERROR(ROUND(AVERAGEIFS(Weekly_Data!$F:$F,Weekly_Data!$A:$A,"Rollout",Weekly_Data!$C:$C,$C59),0),"") | G59: =IFERROR(ROUND(AVERAGEIFS(Weekly_Data!$G:$G,Weekly_Data!$A:$A,"Rollout",Weekly_Data!$C:$C,$C59),0),"") | H59: Moderate Deviation | I59: =SUMIFS(Weekly_Data!$I:$I,Weekly_Data!$A:$A,"Rollout",Weekly_Data!$C:$C,$C59) -> 0 | J59: =SUMIFS(Weekly_Data!$J:$J,Weekly_Data!$A:$A,"Rollout",Weekly_Data!$C:$C,$C59) -> 0
A60: Portfolio | B60: General Scaling | C60: 7 | D60: 2 | E60: 2 | F60: =IFERROR(ROUND(AVERAGEIFS(Weekly_Data!$F:$F,Weekly_Data!$A:$A,"Rollout",Weekly_Data!$C:$C,$C60),0),"") | G60: =IFERROR(ROUND(AVERAGEIFS(Weekly_Data!$G:$G,Weekly_Data!$A:$A,"Rollout",Weekly_Data!$C:$C,$C60),0),"") | H60: Moderate Deviation | I60: =SUMIFS(Weekly_Data!$I:$I,Weekly_Data!$A:$A,"Rollout",Weekly_Data!$C:$C,$C60) -> 0 | J60: =SUMIFS(Weekly_Data!$J:$J,Weekly_Data!$A:$A,"Rollout",Weekly_Data!$C:$C,$C60) -> 0
A61: Portfolio | B61: General Scaling | C61: 8 | D61: 2 | E61: 3 | F61: =IFERROR(ROUND(AVERAGEIFS(Weekly_Data!$F:$F,Weekly_Data!$A:$A,"Rollout",Weekly_Data!$C:$C,$C61),0),"") | G61: =IFERROR(ROUND(AVERAGEIFS(Weekly_Data!$G:$G,Weekly_Data!$A:$A,"Rollout",Weekly_Data!$C:$C,$C61),0),"") | H61: Moderate Deviation | I61: =SUMIFS(Weekly_Data!$I:$I,Weekly_Data!$A:$A,"Rollout",Weekly_Data!$C:$C,$C61) -> 0 | J61: =SUMIFS(Weekly_Data!$J:$J,Weekly_Data!$A:$A,"Rollout",Weekly_Data!$C:$C,$C61) -> 0
A62: Portfolio | B62: General Scaling | C62: 9 | D62: 2 | E62: 4 | F62: =IFERROR(ROUND(AVERAGEIFS(Weekly_Data!$F:$F,Weekly_Data!$A:$A,"Rollout",Weekly_Data!$C:$C,$C62),0),"") | G62: =IFERROR(ROUND(AVERAGEIFS(Weekly_Data!$G:$G,Weekly_Data!$A:$A,"Rollout",Weekly_Data!$C:$C,$C62),0),"") | H62: Moderate Deviation | I62: =SUMIFS(Weekly_Data!$I:$I,Weekly_Data!$A:$A,"Rollout",Weekly_Data!$C:$C,$C62) -> 0 | J62: =SUMIFS(Weekly_Data!$J:$J,Weekly_Data!$A:$A,"Rollout",Weekly_Data!$C:$C,$C62) -> 0
A63: Portfolio | B63: General Scaling | C63: 10 | D63: 3 | E63: 1 | F63: =IFERROR(ROUND(AVERAGEIFS(Weekly_Data!$F:$F,Weekly_Data!$A:$A,"Rollout",Weekly_Data!$C:$C,$C63),0),"") | G63: =IFERROR(ROUND(AVERAGEIFS(Weekly_Data!$G:$G,Weekly_Data!$A:$A,"Rollout",Weekly_Data!$C:$C,$C63),0),"") | H63: Moderate Deviation | I63: =SUMIFS(Weekly_Data!$I:$I,Weekly_Data!$A:$A,"Rollout",Weekly_Data!$C:$C,$C63) -> 0 | J63: =SUMIFS(Weekly_Data!$J:$J,Weekly_Data!$A:$A,"Rollout",Weekly_Data!$C:$C,$C63) -> 0
A64: Portfolio | B64: General Scaling | C64: 11 | D64: 3 | E64: 2 | F64: =IFERROR(ROUND(AVERAGEIFS(Weekly_Data!$F:$F,Weekly_Data!$A:$A,"Rollout",Weekly_Data!$C:$C,$C64),0),"") | G64: =IFERROR(ROUND(AVERAGEIFS(Weekly_Data!$G:$G,Weekly_Data!$A:$A,"Rollout",Weekly_Data!$C:$C,$C64),0),"") | H64: Moderate Deviation | I64: =SUMIFS(Weekly_Data!$I:$I,Weekly_Data!$A:$A,"Rollout",Weekly_Data!$C:$C,$C64) -> 0 | J64: =SUMIFS(Weekly_Data!$J:$J,Weekly_Data!$A:$A,"Rollout",Weekly_Data!$C:$C,$C64) -> 0
A65: Portfolio | B65: General Scaling | C65: 12 | D65: 3 | E65: 3 | F65: =IFERROR(ROUND(AVERAGEIFS(Weekly_Data!$F:$F,Weekly_Data!$A:$A,"Rollout",Weekly_Data!$C:$C,$C65),0),"") | G65: =IFERROR(ROUND(AVERAGEIFS(Weekly_Data!$G:$G,Weekly_Data!$A:$A,"Rollout",Weekly_Data!$C:$C,$C65),0),"") | H65: Moderate Deviation | I65: =SUMIFS(Weekly_Data!$I:$I,Weekly_Data!$A:$A,"Rollout",Weekly_Data!$C:$C,$C65) -> 0 | J65: =SUMIFS(Weekly_Data!$J:$J,Weekly_Data!$A:$A,"Rollout",Weekly_Data!$C:$C,$C65) -> 0
... A77: Portfolio | B77: General Scaling | C77: 24 | D77: 6 | E77: 2 | F77: =IFERROR(ROUND(AVERAGEIFS(Weekly_Data!$F:$F,Weekly_Data!$A:$A,"Rollout",Weekly_Data!$C:$C,$C77),0),"") | G77: =IFERROR(ROUND(AVERAGEIFS(Weekly_Data!$G:$G,Weekly_Data!$A:$A,"Rollout",Weekly_Data!$C:$C,$C77),0),"") | H77: Moderate Deviation | I77: =SUMIFS(Weekly_Data!$I:$I,Weekly_Data!$A:$A,"Rollout",Weekly_Data!$C:$C,$C77) -> 0 | J77: =SUMIFS(Weekly_Data!$J:$J,Weekly_Data!$A:$A,"Rollout",Weekly_Data!$C:$C,$C77) -> 0
...

Sheet Weeks
A1: Week | B1: Month | C1: WeekInMonth | D1: WeekEndDate
A2: 1 | B2: 1 | C2: 1 | D2: 46026
A3: 2 | B3: 1 | C3: 2 | D3: 46033
A4: 3 | B4: 1 | C4: 3 | D4: 46040
A5: 4 | B5: 1 | C5: 4 | D5: 46047
A6: 5 | B6: 1 | C6: 5 | D6: 46054
A7: 6 | B7: 2 | C7: 1 | D7: 46061
A8: 7 | B8: 2 | C8: 2 | D8: 46068
A9: 8 | B9: 2 | C9: 3 | D9: 46075
A10: 9 | B10: 2 | C10: 4 | D10: 46082
A11: 10 | B11: 3 | C11: 1 | D11: 46089
A12: 11 | B12: 3 | C12: 2 | D12: 46096
A13: 12 | B13: 3 | C13: 3 | D13: 46103
... A53: 52 | B53: 12 | C53: 4 | D53: 46383

Sheet Phases
A1: Module | B1: Item | C1: Week | D1: Month | E1: WeekInMonth | F1: PhaseOrder | G1: PhaseName | H1: Progress%
A2: Cheves | B2: Anomaly Detection | C2: 1 | D2: 1 | E2: 1 | F2: 1 | G2: Business Focus | H2: =IFERROR(ROUND(COUNTIFS(Tasks!$A:$A,$A2,Tasks!$B:$B,$B2,Tasks!$C:$C,$G2,Tasks!$I:$I,"<="&INDEX(Weeks!$D:$D,MATCH($C2,Weeks!$A:$A,0)),Tasks!$I:$I,"<>")/COUNTIFS(Tasks!$A:$A,$A2,Tasks!$B:$B,$B2,Tasks!$C:$C,$G2)*100,0),"") -> 100
A3: Cheves | B3: Anomaly Detection | C3: 2 | D3: 1 | E3: 2 | F3: 1 | G3: Business Focus | H3: =IFERROR(ROUND(COUNTIFS(Tasks!$A:$A,$A3,Tasks!$B:$B,$B3,Tasks!$C:$C,$G3,Tasks!$I:$I,"<="&INDEX(Weeks!$D:$D,MATCH($C3,Weeks!$A:$A,0)),Tasks!$I:$I,"<>")/COUNTIFS(Tasks!$A:$A,$A3,Tasks!$B:$B,$B3,Tasks!$C:$C,$G3)*100,0),"") -> 100
A4: Cheves | B4: Anomaly Detection | C4: 3 | D4: 1 | E4: 3 | F4: 1 | G4: Business Focus | H4: =IFERROR(ROUND(COUNTIFS(Tasks!$A:$A,$A4,Tasks!$B:$B,$B4,Tasks!$C:$C,$G4,Tasks!$I:$I,"<="&INDEX(Weeks!$D:$D,MATCH($C4,Weeks!$A:$A,0)),Tasks!$I:$I,"<>")/COUNTIFS(Tasks!$A:$A,$A4,Tasks!$B:$B,$B4,Tasks!$C:$C,$G4)*100,0),"") -> 100
A5: Cheves | B5: Anomaly Detection | C5: 4 | D5: 1 | E5: 4 | F5: 1 | G5: Business Focus | H5: =IFERROR(ROUND(COUNTIFS(Tasks!$A:$A,$A5,Tasks!$B:$B,$B5,Tasks!$C:$C,$G5,Tasks!$I:$I,"<="&INDEX(Weeks!$D:$D,MATCH($C5,Weeks!$A:$A,0)),Tasks!$I:$I,"<>")/COUNTIFS(Tasks!$A:$A,$A5,Tasks!$B:$B,$B5,Tasks!$C:$C,$G5)*100,0),"") -> 100
A6: Cheves | B6: Anomaly Detection | C6: 5 | D6: 1 | E6: 5 | F6: 1 | G6: Business Focus | H6: =IFERROR(ROUND(COUNTIFS(Tasks!$A:$A,$A6,Tasks!$B:$B,$B6,Tasks!$C:$C,$G6,Tasks!$I:$I,"<="&INDEX(Weeks!$D:$D,MATCH($C6,Weeks!$A:$A,0)),Tasks!$I:$I,"<>")/COUNTIFS(Tasks!$A:$A,$A6,Tasks!$B:$B,$B6,Tasks!$C:$C,$G6)*100,0),"") -> 100
A7: Cheves | B7: Anomaly Detection | C7: 6 | D7: 2 | E7: 1 | F7: 1 | G7: Business Focus | H7: =IFERROR(ROUND(COUNTIFS(Tasks!$A:$A,$A7,Tasks!$B:$B,$B7,Tasks!$C:$C,$G7,Tasks!$I:$I,"<="&INDEX(Weeks!$D:$D,MATCH($C7,Weeks!$A:$A,0)),Tasks!$I:$I,"<>")/COUNTIFS(Tasks!$A:$A,$A7,Tasks!$B:$B,$B7,Tasks!$C:$C,$G7)*100,0),"") -> 100
A8: Cheves | B8: Anomaly Detection | C8: 7 | D8: 2 | E8: 2 | F8: 1 | G8: Business Focus | H8: =IFERROR(ROUND(COUNTIFS(Tasks!$A:$A,$A8,Tasks!$B:$B,$B8,Tasks!$C:$C,$G8,Tasks!$I:$I,"<="&INDEX(Weeks!$D:$D,MATCH($C8,Weeks!$A:$A,0)),Tasks!$I:$I,"<>")/COUNTIFS(Tasks!$A:$A,$A8,Tasks!$B:$B,$B8,Tasks!$C:$C,$G8)*100,0),"") -> 100
A9: Cheves | B9: Anomaly Detection | C9: 8 | D9: 2 | E9: 3 | F9: 1 | G9: Business Focus | H9: =IFERROR(ROUND(COUNTIFS(Tasks!$A:$A,$A9,Tasks!$B:$B,$B9,Tasks!$C:$C,$G9,Tasks!$I:$I,"<="&INDEX(Weeks!$D:$D,MATCH($C9,Weeks!$A:$A,0)),Tasks!$I:$I,"<>")/COUNTIFS(Tasks!$A:$A,$A9,Tasks!$B:$B,$B9,Tasks!$C:$C,$G9)*100,0),"") -> 100
A10: Cheves | B10: Anomaly Detection | C10: 9 | D10: 2 | E10: 4 | F10: 1 | G10: Business Focus | H10: =IFERROR(ROUND(COUNTIFS(Tasks!$A:$A,$A10,Tasks!$B:$B,$B10,Tasks!$C:$C,$G10,Tasks!$I:$I,"<="&INDEX(Weeks!$D:$D,MATCH($C10,Weeks!$A:$A,0)),Tasks!$I:$I,"<>")/COUNTIFS(Tasks!$A:$A,$A10,Tasks!$B:$B,$B10,Tasks!$C:$C,$G10)*100,0),"") -> 100
A11: Cheves | B11: Anomaly Detection | C11: 10 | D11: 3 | E11: 1 | F11: 1 | G11: Business Focus | H11: =IFERROR(ROUND(COUNTIFS(Tasks!$A:$A,$A11,Tasks!$B:$B,$B11,Tasks!$C:$C,$G11,Tasks!$I:$I,"<="&INDEX(Weeks!$D:$D,MATCH($C11,Weeks!$A:$A,0)),Tasks!$I:$I,"<>")/COUNTIFS(Tasks!$A:$A,$A11,Tasks!$B:$B,$B11,Tasks!$C:$C,$G11)*100,0),"") -> 100
A12: Cheves | B12: Anomaly Detection | C12: 11 | D12: 3 | E12: 2 | F12: 1 | G12: Business Focus | H12: =IFERROR(ROUND(COUNTIFS(Tasks!$A:$A,$A12,Tasks!$B:$B,$B12,Tasks!$C:$C,$G12,Tasks!$I:$I,"<="&INDEX(Weeks!$D:$D,MATCH($C12,Weeks!$A:$A,0)),Tasks!$I:$I,"<>")/COUNTIFS(Tasks!$A:$A,$A12,Tasks!$B:$B,$B12,Tasks!$C:$C,$G12)*100,0),"") -> 100
A13: Cheves | B13: Anomaly Detection | C13: 12 | D13: 3 | E13: 3 | F13: 1 | G13: Business Focus | H13: =IFERROR(ROUND(COUNTIFS(Tasks!$A:$A,$A13,Tasks!$B:$B,$B13,Tasks!$C:$C,$G13,Tasks!$I:$I,"<="&INDEX(Weeks!$D:$D,MATCH($C13,Weeks!$A:$A,0)),Tasks!$I:$I,"<>")/COUNTIFS(Tasks!$A:$A,$A13,Tasks!$B:$B,$B13,Tasks!$C:$C,$G13)*100,0),"") -> 100
... A3017: SOKnowledge | B3017: Cross-Functional SO Meetings Agent | C3017: 52 | D3017: 12 | E3017: 4 | F3017: 4 | G3017: Deployment | H3017: =IFERROR(ROUND(COUNTIFS(Tasks!$A:$A,$A3017,Tasks!$B:$B,$B3017,Tasks!$C:$C,$G3017,Tasks!$I:$I,"<="&INDEX(Weeks!$D:$D,MATCH($C3017,Weeks!$A:$A,0)),Tasks!$I:$I,"<>")/COUNTIFS(Tasks!$A:$A,$A3017,Tasks!$B:$B,$B3017,Tasks!$C:$C,$G3017)*100,0),"")

Sheet Milestones
A1: Module | B1: Item | C1: MilestoneOrder | D1: Milestone | E1: Done | F1: WeekCompleted | G1: PhaseName
A2: Cheves | B2: Anomaly Detection | C2: 1 | D2: Business alignment | E2: Y | F2: 7 | G2: Business Focus
A3: Cheves | B3: Anomaly Detection | C3: 2 | D3: Data pipeline established | E3: Y | F3: 12 | G3: Data Acquisition
A4: Cheves | B4: Anomaly Detection | C4: 3 | D4: Model validated | E4: Y | F4: 17 | G4: Data Modeling
A5: Cheves | B5: Anomaly Detection | C5: 4 | D5: Operator training | E5: N | G5: Data Validation
A6: Cheves | B6: Anomaly Detection | C6: 5 | D6: Go-live | E6: N | G6: Data Deployment
A7: Cheves | B7: CWS | C7: 1 | D7: Business alignment | E7: Y | F7: 8 | G7: Business Focus
A8: Cheves | B8: CWS | C8: 2 | D8: Data pipeline established | E8: Y | F8: 16 | G8: Data Acquisition
A9: Cheves | B9: CWS | C9: 3 | D9: Model validated | E9: N | G9: Data Modeling
A10: Cheves | B10: CWS | C10: 4 | D10: Operator training | E10: N | G10: Data Validation
A11: Cheves | B11: CWS | C11: 5 | D11: Go-live | E11: N | G11: Data Deployment
A12: Cheves | B12: UH Prediction | C12: 1 | D12: Business alignment | E12: Y | F12: 12 | G12: Business Focus
A13: Cheves | B13: UH Prediction | C13: 2 | D13: Data pipeline established | E13: N | G13: Data Acquisition
A14: Cheves | B14: UH Prediction | C14: 3 | D14: Model validated | E14: N | G14: Data Modeling
A15: Cheves | B15: UH Prediction | C15: 4 | D15: Operator training | E15: N | G15: Data Validation
A16: Cheves | B16: UH Prediction | C16: 5 | D16: Go-live | E16: N | G16: Data Deployment
A17: Rollout | B17: Cahua | C17: 1 | D17: Site assessment | E17: Y | F17: 7 | G17: Business Focus
A18: Rollout | B18: Cahua | C18: 2 | D18: Data connectivity | E18: Y | F18: 12 | G18: Data Acquisition
A19: Rollout | B19: Cahua | C19: 3 | D19: Model deployment | E19: Y | F19: 17 | G19: Data Modeling
A20: Rollout | B20: Cahua | C20: 4 | D20: Operator training | E20: N | G20: Data Validation
A21: Rollout | B21: Cahua | C21: 5 | D21: Go-live | E21: N | G21: Data Deployment
A22: Rollout | B22: Yaupi | C22: 1 | D22: Site assessment | E22: Y | F22: 8 | G22: Business Focus
A23: Rollout | B23: Yaupi | C23: 2 | D23: Data connectivity | E23: Y | F23: 16 | G23: Data Acquisition
A24: Rollout | B24: Yaupi | C24: 3 | D24: Model deployment | E24: N | G24: Data Modeling
A25: Rollout | B25: Yaupi | C25: 4 | D25: Operator training | E25: N | G25: Data Validation
A26: Rollout | B26: Yaupi | C26: 5 | D26: Go-live | E26: N | G26: Data Deployment
A27: Rollout | B27: Malpaso | C27: 1 | D27: Site assessment | E27: Y | F27: 12 | G27: Business Focus
A28: Rollout | B28: Malpaso | C28: 2 | D28: Data connectivity | E28: N | G28: Data Acquisition
A29: Rollout | B29: Malpaso | C29: 3 | D29: Model deployment | E29: N | G29: Data Modeling
A30: Rollout | B30: Malpaso | C30: 4 | D30: Operator training | E30: N | G30: Data Validation
A31: Rollout | B31: Malpaso | C31: 5 | D31: Go-live | E31: N | G31: Data Deployment
A32: AIAgents | B32: Autonomous Anomaly Detection Agent | C32: 1 | D32: Model trained | E32: Y | F32: 7 | G32: Design
A33: AIAgents | B33: Autonomous Anomaly Detection Agent | C33: 2 | D33: Pilot with operators | E33: Y | F33: 12 | G33: Development
A34: AIAgents | B34: Autonomous Anomaly Detection Agent | C34: 3 | D34: Integration with SCADA | E34: Y | F34: 17 | G34: Validation
A35: AIAgents | B35: Autonomous Anomaly Detection Agent | C35: 4 | D35: Full production | E35: N | G35: Deployment
A36: AIAgents | B36: CWS Health Monitoring and Forecasting Agent | C36: 1 | D36: Model trained | E36: Y | F36: 8 | G36: Design
A37: AIAgents | B37: CWS Health Monitoring and Forecasting Agent | C37: 2 | D37: Pilot with operators | E37: Y | F37: 16 | G37: Development
A38: AIAgents | B38: CWS Health Monitoring and Forecasting Agent | C38: 3 | D38: Integration with SCADA | E38: N | G38: Validation
A39: AIAgents | B39: CWS Health Monitoring and Forecasting Agent | C39: 4 | D39: Full production | E39: N | G39: Deployment
A40: AIAgents | B40: HPU Health Monitoring and Forecasting Agent | C40: 1 | D40: Model trained | E40: Y | F40: 12 | G40: Design
...

Sheet Tasks
A1: Module | B1: Item | C1: Phase | D1: TaskName | E1: Status | F1: Responsible | G1: DateCreated | H1: PlannedDate | I1: DateClosed
A2: Cheves | B2: Anomaly Detection | C2: Business Focus | D2: Workshop/Reunión con end-users | E2: In Progress | F2: Kevin | G2: 46023 | I2: 46026
A3: Cheves | B3: Anomaly Detection | C3: Data Acquisition | D3: Mejora de query CDP | E3: Done | G3: 46023 | I3: 46037
A4: Cheves | B4: Anomaly Detection | C4: Data Modeling | D4: Afinación de parámetros | E4: In Progress | G4: 46023
A5: Cheves | B5: Anomaly Detection | C5: Data Validation
A6: Cheves | B6: Anomaly Detection | C6: Data Deployment | D6: Creacion de dashboard | E6: In Progress | F6: Jazmin | G6: 45986 | H6: 46167 | I6: 46183
A7: Cheves | B7: Anomaly Detection | C7: Data Deployment

Sheet Governance_Domains
A1: Domain | B1: Week | C1: Month | D1: WeekInMonth | E1: Stage(0-4) | F1: Cataloged% | G1: OwnerAssigned% | H1: PlanningProgress% | I1: PipelineStatus | J1: DashboardStatus | K1: DatasetsOK% | L1: Issues | M1: Backlog | N1: Notes
A2: Dispatch | B2: 1 | C2: 1 | D2: 1 | E2: 4 | F2: 0 | G2: 0 | H2: 0 | I2: Not Started | J2: Not Started | K2: 0 | L2: 0 | M2: 0 | N2: Pending
A3: Dispatch | B3: 2 | C3: 1 | D3: 2 | E3: 4 | F3: 0 | G3: 0 | H3: 0 | I3: Not Started | J3: Not Started | K3: 0 | L3: 0 | M3: 0 | N3: Pending
A4: Dispatch | B4: 3 | C4: 1 | D4: 3 | E4: 4 | F4: 0 | G4: 0 | H4: 0 | I4: Not Started | J4: Not Started | K4: 0 | L4: 0 | M4: 0 | N4: Domain hasn't reached this stage yet.
A5: Dispatch | B5: 4 | C5: 1 | D5: 4 | E5: 4 | F5: 0 | G5: 0 | H5: 0 | I5: Not Started | J5: Not Started | K5: 0 | L5: 0 | M5: 0 | N5: Domain hasn't reached this stage yet.
A6: Dispatch | B6: 5 | C6: 1 | D6: 5 | E6: 4 | F6: 0 | G6: 0 | H6: 0 | I6: Not Started | J6: Not Started | K6: 0 | L6: 0 | M6: 0 | N6: Domain hasn't reached this stage yet.
A7: Dispatch | B7: 6 | C7: 2 | D7: 1 | E7: 4 | F7: 0 | G7: 0 | H7: 0 | I7: Not Started | J7: Not Started | K7: 0 | L7: 0 | M7: 0 | N7: Domain hasn't reached this stage yet.
A8: Dispatch | B8: 7 | C8: 2 | D8: 2 | E8: 4 | F8: 0 | G8: 0 | H8: 0 | I8: Not Started | J8: Not Started | K8: 0 | L8: 0 | M8: 0 | N8: Domain hasn't reached this stage yet.
A9: Dispatch | B9: 8 | C9: 2 | D9: 3 | E9: 4 | F9: 0 | G9: 0 | H9: 0 | I9: Not Started | J9: Not Started | K9: 0 | L9: 0 | M9: 0 | N9: Domain hasn't reached this stage yet.
A10: Dispatch | B10: 9 | C10: 2 | D10: 4 | E10: 4 | F10: 0 | G10: 0 | H10: 0 | I10: Not Started | J10: Not Started | K10: 0 | L10: 0 | M10: 0 | N10: Domain hasn't reached this stage yet.
A11: Dispatch | B11: 10 | C11: 3 | D11: 1 | E11: 4 | F11: 0 | G11: 0 | H11: 0 | I11: Not Started | J11: Not Started | K11: 0 | L11: 0 | M11: 0 | N11: Domain hasn't reached this stage yet.
A12: Dispatch | B12: 11 | C12: 3 | D12: 2 | E12: 4 | F12: 0 | G12: 0 | H12: 0 | I12: Not Started | J12: Not Started | K12: 0 | L12: 0 | M12: 0 | N12: Domain hasn't reached this stage yet.
A13: Dispatch | B13: 12 | C13: 3 | D13: 3 | E13: 4 | F13: 0 | G13: 0 | H13: 0 | I13: Not Started | J13: Not Started | K13: 0 | L13: 0 | M13: 0 | N13: Domain hasn't reached this stage yet.
... A209: Dams Safety & Civil | B209: 52 | C209: 12 | D209: 4 | E209: 4 | F209: 0 | G209: 0 | H209: 0 | I209: Not Started | J209: Not Started | K209: 0 | L209: 0 | M209: 0 | N209: Domain hasn't reached this stage yet.

Sheet Governance_Datasets
A1: Domain | B1: Dataset | C1: Source | D1: Criticality | E1: Usage | F1: Update Frequency | G1: Origin & Transformations | H1: Known Quality Status | I1: Known Warnings | J1: Owner | K1: Steward | L1: Rule | M1: Dimension | N1: Threshold
A2: O&M | B2: Production / Energy | D2: High | E2: Operational | J2: O&M | K2: J. Ramirez
A3: Asset Management | B3: MAuA / Availability | D3: High | E3: Operational | J3: Asset Management | K3: K. Soto
A4: Dispatch | B4: Loss of Profit | D4: High | E4: Strategic | J4: Dispatch | K4: M. Diaz
A5: O&M | B5: Hydrology | D5: Medium | E5: Operational
A6: Dispatch | B6: SCADA Generation | D6: High | E6: Operational | L6: Maximum deviation from the instrument's certified value | M6: Accuracy | N6: 0.005
A7: Dams Safety & Civil | B7: Dam Instrumentation Readings | D7: High | E7: Operational | J7: Dams Safety & Civil | N7: --
A8: Dams Safety & Civil | B8: Inspection Reports | D8: Medium | E8: Strategic

Sheet Governance_Plan
A1: Domain | B1: TargetStage | C1: TargetDate
A2: Asset Management
A3: Dams Safety & Civil
A4: Dispatch
A5: O&M

Sheet Executive_Cycle_Current
A1: Order | B1: Milestone | C1: PlannedDayOffset | D1: Description | E1: Done | F1: ActualDayOffset
A2: 1 | B2: Month-end | C2: 0 | D2: Reference point: last day of the month. | E2: Y | F2: 0
A3: 2 | B3: Data Updated | C3: 14 | D3: Deadline for teams to update their source data. | E3: Y | F3: 14
A4: 3 | B4: Dashboard Updated | C4: 15 | D4: Official dashboard refresh, one day after the data deadline. | E4: Y | F4: 15
A5: 4 | B5: Monthly Review | C5: 15 | D5: Sustentación with Asset Management leadership. | E5: Y
A6: 5 | B6: FAP Presentation | C6: 30 | D6: Manager presents results at the FAP (4th week of the cycle). | E6: N

Sheet Executive_Cycle_History
A1: Month | B1: PlannedDay | C1: ActualDay | D1: DashboardOnTime | E1: MonthlyReviewDone | F1: FAPPresented
A2: Jan-26 | B2: 0 | C2: 0
A3: Feb-26 | B3: 14 | C3: 14 | D3: Y | E3: Y | F3: Y
A4: Mar-26 | B4: 14 | C4: 16 | D4: Y | E4: Y | F4: Y
A5: Apr-26 | B5: 14 | C5: 15 | D5: Y | E5: Y | F5: Y
A6: May-26 | B6: 14 | C6: 14 | D6: Y | E6: Y | F6: Y
A7: Jun-26 | B7: 14 | C7: 14 | D7: Y | E7: Y | F7: Y
A8: Jul-26 | B8: 12 | C8: 12 | D8: Y | E8: Y | F8: Y
A9: Aug-26 | B9: 14 | C9: 14 | D9: Y | E9: Y | F9: N
A10: Sep-26 | B10: 0 | C10: 0
A11: Oct-26 | B11: 0 | C11: 0
A12: Nov-26 | B12: 0 | C12: 0
A13: Dec-26 | B13: 0 | C13: 0

Sheet Executive_TeamReadiness
A1: Month | B1: Team | C1: DataUpdated | D1: DateUpdated
A2: EJEMPLO - Jul-26 | B2: EJEMPLO - Asset Management | C2: Y

Sheet Executive_Incidents
A1: Month | B1: Description | C1: DateReported | D1: Severity | E1: Status
A2: EJEMPLO - Jul-26 | B2: EJEMPLO - breve descripcion | D2: Medium | E2: Open

Sheet Executive_KPI_Status
A1: Order | B1: KPI | C1: Updated | D1: Validated | E1: Notes
A2: 1 | B2: MAA | C2: Y | D2: Y
A3: 2 | B3: Net Production | C3: Y | D3: Y
A4: 3 | B4: Additional Incomes | C4: Y | D4: Y
A5: 4 | B5: Loss of Profit | C5: Y | D5: Y
A6: 5 | B6: Maintenance Program Compliance | C6: Y | D6: Y
A7: 6 | B7: Regulatory Compliance | C7: Y | D7: Y
A8: 7 | B8: Opex & Capex | C8: Y | D8: Y
A9: 8 | B9: Procurement Plan Compliance | C9: Y | D9: Y
A10: 9 | B10: Risk Management | C10: Y | D10: Y
A11: 10 | B11: Risk Observation | C11: Y | D11: Y

Sheet Team_Load
A1: Week | B1: Person | C1: Module | D1: OpenTickets | E1: ClosedThisWeek
A2: 25 | B2: Kevin | C2: Cheves | D2: =COUNTIFS(Tasks!$A:$A,$C2,Tasks!$F:$F,$B2,Tasks!$G:$G,"<="&INDEX(Weeks!$D:$D,MATCH($A2,Weeks!$A:$A,0)))-COUNTIFS(Tasks!$A:$A,$C2,Tasks!$F:$F,$B2,Tasks!$I:$I,"<="&INDEX(Weeks!$D:$D,MATCH($A2,Weeks!$A:$A,0)),Tasks!$I:$I,"<>") -> 0 | E2: =COUNTIFS(Tasks!$A:$A,$C2,Tasks!$F:$F,$B2,Tasks!$I:$I,">"&INDEX(Weeks!$D:$D,MATCH($A2-1,Weeks!$A:$A,0)),Tasks!$I:$I,"<="&INDEX(Weeks!$D:$D,MATCH($A2,Weeks!$A:$A,0)),Tasks!$I:$I,"<>") -> 0
A3: 25 | B3: Kevin | C3: Rollout | D3: =COUNTIFS(Tasks!$A:$A,$C3,Tasks!$F:$F,$B3,Tasks!$G:$G,"<="&INDEX(Weeks!$D:$D,MATCH($A3,Weeks!$A:$A,0)))-COUNTIFS(Tasks!$A:$A,$C3,Tasks!$F:$F,$B3,Tasks!$I:$I,"<="&INDEX(Weeks!$D:$D,MATCH($A3,Weeks!$A:$A,0)),Tasks!$I:$I,"<>") -> 0 | E3: =COUNTIFS(Tasks!$A:$A,$C3,Tasks!$F:$F,$B3,Tasks!$I:$I,">"&INDEX(Weeks!$D:$D,MATCH($A3-1,Weeks!$A:$A,0)),Tasks!$I:$I,"<="&INDEX(Weeks!$D:$D,MATCH($A3,Weeks!$A:$A,0)),Tasks!$I:$I,"<>") -> 0
A4: 25 | B4: Kevin | C4: AIAgents | D4: =COUNTIFS(Tasks!$A:$A,$C4,Tasks!$F:$F,$B4,Tasks!$G:$G,"<="&INDEX(Weeks!$D:$D,MATCH($A4,Weeks!$A:$A,0)))-COUNTIFS(Tasks!$A:$A,$C4,Tasks!$F:$F,$B4,Tasks!$I:$I,"<="&INDEX(Weeks!$D:$D,MATCH($A4,Weeks!$A:$A,0)),Tasks!$I:$I,"<>") -> 0 | E4: =COUNTIFS(Tasks!$A:$A,$C4,Tasks!$F:$F,$B4,Tasks!$I:$I,">"&INDEX(Weeks!$D:$D,MATCH($A4-1,Weeks!$A:$A,0)),Tasks!$I:$I,"<="&INDEX(Weeks!$D:$D,MATCH($A4,Weeks!$A:$A,0)),Tasks!$I:$I,"<>") -> 0
A5: 25 | B5: Kevin | C5: SOKnowledge | D5: =COUNTIFS(Tasks!$A:$A,$C5,Tasks!$F:$F,$B5,Tasks!$G:$G,"<="&INDEX(Weeks!$D:$D,MATCH($A5,Weeks!$A:$A,0)))-COUNTIFS(Tasks!$A:$A,$C5,Tasks!$F:$F,$B5,Tasks!$I:$I,"<="&INDEX(Weeks!$D:$D,MATCH($A5,Weeks!$A:$A,0)),Tasks!$I:$I,"<>") -> 0 | E5: =COUNTIFS(Tasks!$A:$A,$C5,Tasks!$F:$F,$B5,Tasks!$I:$I,">"&INDEX(Weeks!$D:$D,MATCH($A5-1,Weeks!$A:$A,0)),Tasks!$I:$I,"<="&INDEX(Weeks!$D:$D,MATCH($A5,Weeks!$A:$A,0)),Tasks!$I:$I,"<>") -> 0
A6: 25 | B6: Jazmin | C6: Cheves | D6: =COUNTIFS(Tasks!$A:$A,$C6,Tasks!$F:$F,$B6,Tasks!$G:$G,"<="&INDEX(Weeks!$D:$D,MATCH($A6,Weeks!$A:$A,0)))-COUNTIFS(Tasks!$A:$A,$C6,Tasks!$F:$F,$B6,Tasks!$I:$I,"<="&INDEX(Weeks!$D:$D,MATCH($A6,Weeks!$A:$A,0)),Tasks!$I:$I,"<>") -> 0 | E6: =COUNTIFS(Tasks!$A:$A,$C6,Tasks!$F:$F,$B6,Tasks!$I:$I,">"&INDEX(Weeks!$D:$D,MATCH($A6-1,Weeks!$A:$A,0)),Tasks!$I:$I,"<="&INDEX(Weeks!$D:$D,MATCH($A6,Weeks!$A:$A,0)),Tasks!$I:$I,"<>") -> 0
A7: 25 | B7: Jazmin | C7: Rollout | D7: =COUNTIFS(Tasks!$A:$A,$C7,Tasks!$F:$F,$B7,Tasks!$G:$G,"<="&INDEX(Weeks!$D:$D,MATCH($A7,Weeks!$A:$A,0)))-COUNTIFS(Tasks!$A:$A,$C7,Tasks!$F:$F,$B7,Tasks!$I:$I,"<="&INDEX(Weeks!$D:$D,MATCH($A7,Weeks!$A:$A,0)),Tasks!$I:$I,"<>") -> 0 | E7: =COUNTIFS(Tasks!$A:$A,$C7,Tasks!$F:$F,$B7,Tasks!$I:$I,">"&INDEX(Weeks!$D:$D,MATCH($A7-1,Weeks!$A:$A,0)),Tasks!$I:$I,"<="&INDEX(Weeks!$D:$D,MATCH($A7,Weeks!$A:$A,0)),Tasks!$I:$I,"<>") -> 0
A8: 25 | B8: Jazmin | C8: AIAgents | D8: =COUNTIFS(Tasks!$A:$A,$C8,Tasks!$F:$F,$B8,Tasks!$G:$G,"<="&INDEX(Weeks!$D:$D,MATCH($A8,Weeks!$A:$A,0)))-COUNTIFS(Tasks!$A:$A,$C8,Tasks!$F:$F,$B8,Tasks!$I:$I,"<="&INDEX(Weeks!$D:$D,MATCH($A8,Weeks!$A:$A,0)),Tasks!$I:$I,"<>") -> 0 | E8: =COUNTIFS(Tasks!$A:$A,$C8,Tasks!$F:$F,$B8,Tasks!$I:$I,">"&INDEX(Weeks!$D:$D,MATCH($A8-1,Weeks!$A:$A,0)),Tasks!$I:$I,"<="&INDEX(Weeks!$D:$D,MATCH($A8,Weeks!$A:$A,0)),Tasks!$I:$I,"<>") -> 0
A9: 25 | B9: Jazmin | C9: SOKnowledge | D9: =COUNTIFS(Tasks!$A:$A,$C9,Tasks!$F:$F,$B9,Tasks!$G:$G,"<="&INDEX(Weeks!$D:$D,MATCH($A9,Weeks!$A:$A,0)))-COUNTIFS(Tasks!$A:$A,$C9,Tasks!$F:$F,$B9,Tasks!$I:$I,"<="&INDEX(Weeks!$D:$D,MATCH($A9,Weeks!$A:$A,0)),Tasks!$I:$I,"<>") -> 0 | E9: =COUNTIFS(Tasks!$A:$A,$C9,Tasks!$F:$F,$B9,Tasks!$I:$I,">"&INDEX(Weeks!$D:$D,MATCH($A9-1,Weeks!$A:$A,0)),Tasks!$I:$I,"<="&INDEX(Weeks!$D:$D,MATCH($A9,Weeks!$A:$A,0)),Tasks!$I:$I,"<>") -> 0
A10: 26 | B10: Kevin | C10: Cheves | D10: =COUNTIFS(Tasks!$A:$A,$C10,Tasks!$F:$F,$B10,Tasks!$G:$G,"<="&INDEX(Weeks!$D:$D,MATCH($A10,Weeks!$A:$A,0)))-COUNTIFS(Tasks!$A:$A,$C10,Tasks!$F:$F,$B10,Tasks!$I:$I,"<="&INDEX(Weeks!$D:$D,MATCH($A10,Weeks!$A:$A,0)),Tasks!$I:$I,"<>") -> 0 | E10: =COUNTIFS(Tasks!$A:$A,$C10,Tasks!$F:$F,$B10,Tasks!$I:$I,">"&INDEX(Weeks!$D:$D,MATCH($A10-1,Weeks!$A:$A,0)),Tasks!$I:$I,"<="&INDEX(Weeks!$D:$D,MATCH($A10,Weeks!$A:$A,0)),Tasks!$I:$I,"<>") -> 0
A11: 26 | B11: Kevin | C11: Rollout | D11: =COUNTIFS(Tasks!$A:$A,$C11,Tasks!$F:$F,$B11,Tasks!$G:$G,"<="&INDEX(Weeks!$D:$D,MATCH($A11,Weeks!$A:$A,0)))-COUNTIFS(Tasks!$A:$A,$C11,Tasks!$F:$F,$B11,Tasks!$I:$I,"<="&INDEX(Weeks!$D:$D,MATCH($A11,Weeks!$A:$A,0)),Tasks!$I:$I,"<>") -> 0 | E11: =COUNTIFS(Tasks!$A:$A,$C11,Tasks!$F:$F,$B11,Tasks!$I:$I,">"&INDEX(Weeks!$D:$D,MATCH($A11-1,Weeks!$A:$A,0)),Tasks!$I:$I,"<="&INDEX(Weeks!$D:$D,MATCH($A11,Weeks!$A:$A,0)),Tasks!$I:$I,"<>") -> 0
A12: 26 | B12: Kevin | C12: AIAgents | D12: =COUNTIFS(Tasks!$A:$A,$C12,Tasks!$F:$F,$B12,Tasks!$G:$G,"<="&INDEX(Weeks!$D:$D,MATCH($A12,Weeks!$A:$A,0)))-COUNTIFS(Tasks!$A:$A,$C12,Tasks!$F:$F,$B12,Tasks!$I:$I,"<="&INDEX(Weeks!$D:$D,MATCH($A12,Weeks!$A:$A,0)),Tasks!$I:$I,"<>") -> 0 | E12: =COUNTIFS(Tasks!$A:$A,$C12,Tasks!$F:$F,$B12,Tasks!$I:$I,">"&INDEX(Weeks!$D:$D,MATCH($A12-1,Weeks!$A:$A,0)),Tasks!$I:$I,"<="&INDEX(Weeks!$D:$D,MATCH($A12,Weeks!$A:$A,0)),Tasks!$I:$I,"<>") -> 0
A13: 26 | B13: Kevin | C13: SOKnowledge | D13: =COUNTIFS(Tasks!$A:$A,$C13,Tasks!$F:$F,$B13,Tasks!$G:$G,"<="&INDEX(Weeks!$D:$D,MATCH($A13,Weeks!$A:$A,0)))-COUNTIFS(Tasks!$A:$A,$C13,Tasks!$F:$F,$B13,Tasks!$I:$I,"<="&INDEX(Weeks!$D:$D,MATCH($A13,Weeks!$A:$A,0)),Tasks!$I:$I,"<>") -> 0 | E13: =COUNTIFS(Tasks!$A:$A,$C13,Tasks!$F:$F,$B13,Tasks!$I:$I,">"&INDEX(Weeks!$D:$D,MATCH($A13-1,Weeks!$A:$A,0)),Tasks!$I:$I,"<="&INDEX(Weeks!$D:$D,MATCH($A13,Weeks!$A:$A,0)),Tasks!$I:$I,"<>") -> 0
... A193: 48 | B193: Jazmin | C193: SOKnowledge | D193: =COUNTIFS(Tasks!$A:$A,$C193,Tasks!$F:$F,$B193,Tasks!$G:$G,"<="&INDEX(Weeks!$D:$D,MATCH($A193,Weeks!$A:$A,0)))-COUNTIFS(Tasks!$A:$A,$C193,Tasks!$F:$F,$B193,Tasks!$I:$I,"<="&INDEX(Weeks!$D:$D,MATCH($A193,Weeks!$A:$A,0)),Tasks!$I:$I,"<>") -> 0 | E193: =COUNTIFS(Tasks!$A:$A,$C193,Tasks!$F:$F,$B193,Tasks!$I:$I,">"&INDEX(Weeks!$D:$D,MATCH($A193-1,Weeks!$A:$A,0)),Tasks!$I:$I,"<="&INDEX(Weeks!$D:$D,MATCH($A193,Weeks!$A:$A,0)),Tasks!$I:$I,"<>") -> 0
